{
  try {
    runFlow("validate");
    fail("Was expecting a failure");
  }
 catch (  Exception e) {
    Throwable cause=ExceptionUtils.getRootCause(e);
    assertThat(cause,is(instanceOf(ValidationException.class)));
  }
}
