{
  final Exception exception=new RuntimeException();
  when(next.process(any())).thenThrow(exception);
  try {
    messageProcessor.process(event);
    fail("Should have failed");
  }
 catch (  Exception e) {
    verify(next).process(event);
    verify(interceptingCallback,never()).onSuccess(any());
    verify(interceptingCallback).onException(exception);
    verify(interceptingCallback).onComplete();
  }
}
