{
  try {
    runFlow(flowName,getTestEvent(""));
    fail("was expecting a failure");
  }
 catch (  Exception e) {
    Throwable cause=ExceptionUtils.getRootCause(e);
    assertThat(CUSTOM_VALIDATOR_EXCEPTION,is(sameInstance(cause)));
  }
}
