{
  callThrowException(503,"This is an exception");
}
